[2022-06-20 05:16:57,140] {taskinstance.py:1160} INFO - Dependencies all met for <TaskInstance: sales.extract_data __airflow_temporary_run_2022-06-20T08:16:55.108265+00:00__ [queued]>
[2022-06-20 05:16:57,159] {taskinstance.py:1160} INFO - Dependencies all met for <TaskInstance: sales.extract_data __airflow_temporary_run_2022-06-20T08:16:55.108265+00:00__ [queued]>
[2022-06-20 05:16:57,160] {taskinstance.py:1357} INFO - 
--------------------------------------------------------------------------------
[2022-06-20 05:16:57,160] {taskinstance.py:1358} INFO - Starting attempt 1 of 1
[2022-06-20 05:16:57,160] {taskinstance.py:1359} INFO - 
--------------------------------------------------------------------------------
[2022-06-20 05:16:57,182] {taskinstance.py:1378} INFO - Executing <Task(PythonOperator): extract_data> on 2022-01-01 00:00:00+00:00
[2022-06-20 05:16:57,195] {standard_task_runner.py:52} INFO - Started process 26545 to run task
[2022-06-20 05:16:57,201] {standard_task_runner.py:79} INFO - Running: ['airflow', 'tasks', 'run', 'sales', 'extract_data', '__airflow_temporary_run_2022-06-20T08:16:55.108265+00:00__', '--job-id', '742', '--raw', '--subdir', 'DAGS_FOLDER/sales.py', '--cfg-path', '/tmp/tmp90b8ahwh', '--error-file', '/tmp/tmpljk22oc8']
[2022-06-20 05:16:57,202] {standard_task_runner.py:80} INFO - Job 742: Subtask extract_data
[2022-06-20 05:16:57,322] {task_command.py:370} INFO - Running <TaskInstance: sales.extract_data __airflow_temporary_run_2022-06-20T08:16:55.108265+00:00__ [running]> on host uiliam-Vostro-15-3515
[2022-06-20 05:16:57,431] {taskinstance.py:1570} INFO - Exporting the following env vars:
AIRFLOW_CTX_DAG_OWNER=airflow
AIRFLOW_CTX_DAG_ID=sales
AIRFLOW_CTX_TASK_ID=extract_data
AIRFLOW_CTX_EXECUTION_DATE=2022-01-01T00:00:00+00:00
AIRFLOW_CTX_TRY_NUMBER=1
AIRFLOW_CTX_DAG_RUN_ID=__airflow_temporary_run_2022-06-20T08:16:55.108265+00:00__
[2022-06-20 05:16:57,446] {taskinstance.py:1890} ERROR - Task failed with exception
Traceback (most recent call last):
  File "/home/uiliam/sandbox/lib/python3.9/site-packages/sqlalchemy/engine/base.py", line 1705, in _execute_context
    self.dialect.do_execute(
  File "/home/uiliam/sandbox/lib/python3.9/site-packages/sqlalchemy/engine/default.py", line 716, in do_execute
    cursor.execute(statement, parameters)
psycopg2.errors.UndefinedTable: missing FROM-clause entry for table "c"
LINE 1: select distinct c.customerNumber, customerName, contactLastN...
                        ^


The above exception was the direct cause of the following exception:

Traceback (most recent call last):
  File "/home/uiliam/sandbox/lib/python3.9/site-packages/airflow/operators/python.py", line 171, in execute
    return_value = self.execute_callable()
  File "/home/uiliam/sandbox/lib/python3.9/site-packages/airflow/operators/python.py", line 189, in execute_callable
    return self.python_callable(*self.op_args, **self.op_kwargs)
  File "/home/uiliam/airflow/dags/sales.py", line 23, in extract
    df_cost = pd.read_sql_query("select distinct c.customerNumber, customerName, contactLastName, \
  File "/home/uiliam/sandbox/lib/python3.9/site-packages/pandas/io/sql.py", line 399, in read_sql_query
    return pandas_sql.read_query(
  File "/home/uiliam/sandbox/lib/python3.9/site-packages/pandas/io/sql.py", line 1557, in read_query
    result = self.execute(*args)
  File "/home/uiliam/sandbox/lib/python3.9/site-packages/pandas/io/sql.py", line 1402, in execute
    return self.connectable.execution_options().execute(*args, **kwargs)
  File "<string>", line 2, in execute
  File "/home/uiliam/sandbox/lib/python3.9/site-packages/sqlalchemy/util/deprecations.py", line 390, in warned
    return fn(*args, **kwargs)
  File "/home/uiliam/sandbox/lib/python3.9/site-packages/sqlalchemy/engine/base.py", line 3037, in execute
    return connection.execute(statement, *multiparams, **params)
  File "/home/uiliam/sandbox/lib/python3.9/site-packages/sqlalchemy/engine/base.py", line 1185, in execute
    return self._exec_driver_sql(
  File "/home/uiliam/sandbox/lib/python3.9/site-packages/sqlalchemy/engine/base.py", line 1484, in _exec_driver_sql
    ret = self._execute_context(
  File "/home/uiliam/sandbox/lib/python3.9/site-packages/sqlalchemy/engine/base.py", line 1748, in _execute_context
    self._handle_dbapi_exception(
  File "/home/uiliam/sandbox/lib/python3.9/site-packages/sqlalchemy/engine/base.py", line 1929, in _handle_dbapi_exception
    util.raise_(
  File "/home/uiliam/sandbox/lib/python3.9/site-packages/sqlalchemy/util/compat.py", line 211, in raise_
    raise exception
  File "/home/uiliam/sandbox/lib/python3.9/site-packages/sqlalchemy/engine/base.py", line 1705, in _execute_context
    self.dialect.do_execute(
  File "/home/uiliam/sandbox/lib/python3.9/site-packages/sqlalchemy/engine/default.py", line 716, in do_execute
    cursor.execute(statement, parameters)
sqlalchemy.exc.ProgrammingError: (psycopg2.errors.UndefinedTable) missing FROM-clause entry for table "c"
LINE 1: select distinct c.customerNumber, customerName, contactLastN...
                        ^

[SQL: select distinct c.customerNumber, customerName, contactLastName,                 contactFirstName, phone, addressLine1, addressLine2, city, state,                 postalCode, country, salesRepEmployeeNumber, creditLimit from customers]
(Background on this error at: http://sqlalche.me/e/14/f405)
[2022-06-20 05:16:57,464] {taskinstance.py:1396} INFO - Marking task as FAILED. dag_id=sales, task_id=extract_data, execution_date=20220101T000000, start_date=20220620T081657, end_date=20220620T081657
[2022-06-20 05:16:57,482] {standard_task_runner.py:92} ERROR - Failed to execute job 742 for task extract_data ((psycopg2.errors.UndefinedTable) missing FROM-clause entry for table "c"
LINE 1: select distinct c.customerNumber, customerName, contactLastN...
                        ^

[SQL: select distinct c.customerNumber, customerName, contactLastName,                 contactFirstName, phone, addressLine1, addressLine2, city, state,                 postalCode, country, salesRepEmployeeNumber, creditLimit from customers]
(Background on this error at: http://sqlalche.me/e/14/f405); 26545)
[2022-06-20 05:16:57,532] {local_task_job.py:156} INFO - Task exited with return code 1
[2022-06-20 05:16:57,584] {local_task_job.py:273} INFO - 0 downstream tasks scheduled from follow-on schedule check
