[2022-06-05 21:45:26,427] {taskinstance.py:1160} INFO - Dependencies all met for <TaskInstance: census.populate_table scheduled__2022-06-06T00:44:39.034795+00:00 [queued]>
[2022-06-05 21:45:26,445] {taskinstance.py:1160} INFO - Dependencies all met for <TaskInstance: census.populate_table scheduled__2022-06-06T00:44:39.034795+00:00 [queued]>
[2022-06-05 21:45:26,446] {taskinstance.py:1357} INFO - 
--------------------------------------------------------------------------------
[2022-06-05 21:45:26,446] {taskinstance.py:1358} INFO - Starting attempt 1 of 1
[2022-06-05 21:45:26,446] {taskinstance.py:1359} INFO - 
--------------------------------------------------------------------------------
[2022-06-05 21:45:26,465] {taskinstance.py:1378} INFO - Executing <Task(PythonOperator): populate_table> on 2022-06-06 00:44:39.034795+00:00
[2022-06-05 21:45:26,472] {standard_task_runner.py:52} INFO - Started process 19195 to run task
[2022-06-05 21:45:26,477] {standard_task_runner.py:79} INFO - Running: ['airflow', 'tasks', 'run', 'census', 'populate_table', 'scheduled__2022-06-06T00:44:39.034795+00:00', '--job-id', '1135', '--raw', '--subdir', 'DAGS_FOLDER/dag.py', '--cfg-path', '/tmp/tmpilhlbztb', '--error-file', '/tmp/tmpyfvxddsq']
[2022-06-05 21:45:26,478] {standard_task_runner.py:80} INFO - Job 1135: Subtask populate_table
[2022-06-05 21:45:26,554] {task_command.py:370} INFO - Running <TaskInstance: census.populate_table scheduled__2022-06-06T00:44:39.034795+00:00 [running]> on host uiliam-Vostro-15-3515
[2022-06-05 21:45:26,647] {taskinstance.py:1570} INFO - Exporting the following env vars:
AIRFLOW_CTX_DAG_OWNER=airflow
AIRFLOW_CTX_DAG_ID=census
AIRFLOW_CTX_TASK_ID=populate_table
AIRFLOW_CTX_EXECUTION_DATE=2022-06-06T00:44:39.034795+00:00
AIRFLOW_CTX_TRY_NUMBER=1
AIRFLOW_CTX_DAG_RUN_ID=scheduled__2022-06-06T00:44:39.034795+00:00
[2022-06-05 21:45:26,648] {taskinstance.py:1890} ERROR - Task failed with exception
Traceback (most recent call last):
  File "/home/uiliam/sandbox/lib/python3.9/site-packages/airflow/operators/python.py", line 171, in execute
    return_value = self.execute_callable()
  File "/home/uiliam/sandbox/lib/python3.9/site-packages/airflow/operators/python.py", line 189, in execute_callable
    return self.python_callable(*self.op_args, **self.op_kwargs)
  File "/home/uiliam/airflow/dags/populate.py", line 18, in populate_table
    df = df.iloc[:qtd]
AttributeError: 'NoneType' object has no attribute 'iloc'
[2022-06-05 21:45:26,663] {taskinstance.py:1396} INFO - Marking task as FAILED. dag_id=census, task_id=populate_table, execution_date=20220606T004439, start_date=20220606T004526, end_date=20220606T004526
[2022-06-05 21:45:26,680] {standard_task_runner.py:92} ERROR - Failed to execute job 1135 for task populate_table ('NoneType' object has no attribute 'iloc'; 19195)
[2022-06-05 21:45:26,729] {local_task_job.py:156} INFO - Task exited with return code 1
[2022-06-05 21:45:26,777] {local_task_job.py:273} INFO - 0 downstream tasks scheduled from follow-on schedule check
