[2022-06-05 21:42:47,113] {taskinstance.py:1160} INFO - Dependencies all met for <TaskInstance: census.populate_table scheduled__2022-06-06T00:41:54.338235+00:00 [queued]>
[2022-06-05 21:42:47,131] {taskinstance.py:1160} INFO - Dependencies all met for <TaskInstance: census.populate_table scheduled__2022-06-06T00:41:54.338235+00:00 [queued]>
[2022-06-05 21:42:47,131] {taskinstance.py:1357} INFO - 
--------------------------------------------------------------------------------
[2022-06-05 21:42:47,132] {taskinstance.py:1358} INFO - Starting attempt 1 of 1
[2022-06-05 21:42:47,132] {taskinstance.py:1359} INFO - 
--------------------------------------------------------------------------------
[2022-06-05 21:42:47,150] {taskinstance.py:1378} INFO - Executing <Task(PythonOperator): populate_table> on 2022-06-06 00:41:54.338235+00:00
[2022-06-05 21:42:47,160] {standard_task_runner.py:52} INFO - Started process 16301 to run task
[2022-06-05 21:42:47,164] {standard_task_runner.py:79} INFO - Running: ['airflow', 'tasks', 'run', 'census', 'populate_table', 'scheduled__2022-06-06T00:41:54.338235+00:00', '--job-id', '1123', '--raw', '--subdir', 'DAGS_FOLDER/dag.py', '--cfg-path', '/tmp/tmpieun_8m0', '--error-file', '/tmp/tmp872x09bx']
[2022-06-05 21:42:47,165] {standard_task_runner.py:80} INFO - Job 1123: Subtask populate_table
[2022-06-05 21:42:47,237] {task_command.py:370} INFO - Running <TaskInstance: census.populate_table scheduled__2022-06-06T00:41:54.338235+00:00 [running]> on host uiliam-Vostro-15-3515
[2022-06-05 21:42:47,331] {taskinstance.py:1570} INFO - Exporting the following env vars:
AIRFLOW_CTX_DAG_OWNER=airflow
AIRFLOW_CTX_DAG_ID=census
AIRFLOW_CTX_TASK_ID=populate_table
AIRFLOW_CTX_EXECUTION_DATE=2022-06-06T00:41:54.338235+00:00
AIRFLOW_CTX_TRY_NUMBER=1
AIRFLOW_CTX_DAG_RUN_ID=scheduled__2022-06-06T00:41:54.338235+00:00
[2022-06-05 21:42:47,333] {taskinstance.py:1890} ERROR - Task failed with exception
Traceback (most recent call last):
  File "/home/uiliam/sandbox/lib/python3.9/site-packages/airflow/operators/python.py", line 171, in execute
    return_value = self.execute_callable()
  File "/home/uiliam/sandbox/lib/python3.9/site-packages/airflow/operators/python.py", line 189, in execute_callable
    return self.python_callable(*self.op_args, **self.op_kwargs)
  File "/home/uiliam/airflow/dags/populate.py", line 15, in populate_table
    print(df.head())
AttributeError: 'NoneType' object has no attribute 'head'
[2022-06-05 21:42:47,348] {taskinstance.py:1396} INFO - Marking task as FAILED. dag_id=census, task_id=populate_table, execution_date=20220606T004154, start_date=20220606T004247, end_date=20220606T004247
[2022-06-05 21:42:47,366] {standard_task_runner.py:92} ERROR - Failed to execute job 1123 for task populate_table ('NoneType' object has no attribute 'head'; 16301)
[2022-06-05 21:42:47,416] {local_task_job.py:156} INFO - Task exited with return code 1
[2022-06-05 21:42:47,464] {local_task_job.py:273} INFO - 0 downstream tasks scheduled from follow-on schedule check
