[2022-06-05 01:35:10,742] {taskinstance.py:1160} INFO - Dependencies all met for <TaskInstance: census.controle_fluxo scheduled__2022-06-05T03:00:00+00:00 [queued]>
[2022-06-05 01:35:10,760] {taskinstance.py:1160} INFO - Dependencies all met for <TaskInstance: census.controle_fluxo scheduled__2022-06-05T03:00:00+00:00 [queued]>
[2022-06-05 01:35:10,760] {taskinstance.py:1357} INFO - 
--------------------------------------------------------------------------------
[2022-06-05 01:35:10,760] {taskinstance.py:1358} INFO - Starting attempt 1 of 1
[2022-06-05 01:35:10,760] {taskinstance.py:1359} INFO - 
--------------------------------------------------------------------------------
[2022-06-05 01:35:10,784] {taskinstance.py:1378} INFO - Executing <Task(PythonOperator): controle_fluxo> on 2022-06-05 03:00:00+00:00
[2022-06-05 01:35:10,795] {standard_task_runner.py:52} INFO - Started process 10752 to run task
[2022-06-05 01:35:10,802] {standard_task_runner.py:79} INFO - Running: ['airflow', 'tasks', 'run', 'census', 'controle_fluxo', 'scheduled__2022-06-05T03:00:00+00:00', '--job-id', '808', '--raw', '--subdir', 'DAGS_FOLDER/dag.py', '--cfg-path', '/tmp/tmpmqknocur', '--error-file', '/tmp/tmpxrjrp9xy']
[2022-06-05 01:35:10,804] {standard_task_runner.py:80} INFO - Job 808: Subtask controle_fluxo
[2022-06-05 01:35:10,895] {task_command.py:370} INFO - Running <TaskInstance: census.controle_fluxo scheduled__2022-06-05T03:00:00+00:00 [running]> on host uiliam-Vostro-15-3515
[2022-06-05 01:35:11,028] {taskinstance.py:1570} INFO - Exporting the following env vars:
AIRFLOW_CTX_DAG_OWNER=airflow
AIRFLOW_CTX_DAG_ID=census
AIRFLOW_CTX_TASK_ID=controle_fluxo
AIRFLOW_CTX_EXECUTION_DATE=2022-06-05T03:00:00+00:00
AIRFLOW_CTX_TRY_NUMBER=1
AIRFLOW_CTX_DAG_RUN_ID=scheduled__2022-06-05T03:00:00+00:00
[2022-06-05 01:35:11,618] {taskinstance.py:1890} ERROR - Task failed with exception
Traceback (most recent call last):
  File "/home/uiliam/sandbox/lib/python3.9/site-packages/airflow/operators/python.py", line 171, in execute
    return_value = self.execute_callable()
  File "/home/uiliam/sandbox/lib/python3.9/site-packages/airflow/operators/python.py", line 189, in execute_callable
    return self.python_callable(*self.op_args, **self.op_kwargs)
  File "/home/uiliam/airflow/dags/census.py", line 100, in controller_fluxo
    df = df.iloc[init:init + quant]
AttributeError: 'NoneType' object has no attribute 'iloc'
[2022-06-05 01:35:11,634] {taskinstance.py:1396} INFO - Marking task as FAILED. dag_id=census, task_id=controle_fluxo, execution_date=20220605T030000, start_date=20220605T043510, end_date=20220605T043511
[2022-06-05 01:35:11,653] {standard_task_runner.py:92} ERROR - Failed to execute job 808 for task controle_fluxo ('NoneType' object has no attribute 'iloc'; 10752)
[2022-06-05 01:35:11,697] {local_task_job.py:156} INFO - Task exited with return code 1
[2022-06-05 01:35:11,770] {local_task_job.py:273} INFO - 0 downstream tasks scheduled from follow-on schedule check
[2022-06-05 01:46:48,710] {taskinstance.py:1160} INFO - Dependencies all met for <TaskInstance: census.controle_fluxo scheduled__2022-06-05T03:00:00+00:00 [queued]>
[2022-06-05 01:46:48,726] {taskinstance.py:1160} INFO - Dependencies all met for <TaskInstance: census.controle_fluxo scheduled__2022-06-05T03:00:00+00:00 [queued]>
[2022-06-05 01:46:48,726] {taskinstance.py:1357} INFO - 
--------------------------------------------------------------------------------
[2022-06-05 01:46:48,726] {taskinstance.py:1358} INFO - Starting attempt 1 of 1
[2022-06-05 01:46:48,726] {taskinstance.py:1359} INFO - 
--------------------------------------------------------------------------------
[2022-06-05 01:46:48,746] {taskinstance.py:1378} INFO - Executing <Task(PythonOperator): controle_fluxo> on 2022-06-05 03:00:00+00:00
[2022-06-05 01:46:48,754] {standard_task_runner.py:52} INFO - Started process 15586 to run task
[2022-06-05 01:46:48,759] {standard_task_runner.py:79} INFO - Running: ['airflow', 'tasks', 'run', 'census', 'controle_fluxo', 'scheduled__2022-06-05T03:00:00+00:00', '--job-id', '814', '--raw', '--subdir', 'DAGS_FOLDER/dag.py', '--cfg-path', '/tmp/tmp3rpwt91z', '--error-file', '/tmp/tmphmw4zi97']
[2022-06-05 01:46:48,759] {standard_task_runner.py:80} INFO - Job 814: Subtask controle_fluxo
[2022-06-05 01:46:48,833] {task_command.py:370} INFO - Running <TaskInstance: census.controle_fluxo scheduled__2022-06-05T03:00:00+00:00 [running]> on host uiliam-Vostro-15-3515
[2022-06-05 01:46:48,939] {taskinstance.py:1570} INFO - Exporting the following env vars:
AIRFLOW_CTX_DAG_OWNER=airflow
AIRFLOW_CTX_DAG_ID=census
AIRFLOW_CTX_TASK_ID=controle_fluxo
AIRFLOW_CTX_EXECUTION_DATE=2022-06-05T03:00:00+00:00
AIRFLOW_CTX_TRY_NUMBER=1
AIRFLOW_CTX_DAG_RUN_ID=scheduled__2022-06-05T03:00:00+00:00
[2022-06-05 01:46:49,379] {python.py:173} INFO - Done. Returned value was: None
[2022-06-05 01:46:49,399] {taskinstance.py:1396} INFO - Marking task as SUCCESS. dag_id=census, task_id=controle_fluxo, execution_date=20220605T030000, start_date=20220605T044648, end_date=20220605T044649
[2022-06-05 01:46:49,452] {local_task_job.py:156} INFO - Task exited with return code 0
[2022-06-05 01:46:49,506] {local_task_job.py:273} INFO - 1 downstream tasks scheduled from follow-on schedule check
